<?xml version="1.0" ?>
<robot name="rover" xmlns:xacro="http://www.ros.org/wiki/xacro">

  <xacro:property name="chassis_mass" value="10.0"/>
  <xacro:property name="wheel_mass" value="1.5"/>

  <link name="base_footprint"/>
  
  <joint name="base_joint" type="fixed">
    <parent link="base_footprint"/>
    <child link="base_link"/>
    <origin xyz="0 0 0.15" rpy="0 0 0"/>
  </joint>

  <link name="base_link">
    <visual>
      <geometry><box size="0.6 0.4 0.2"/></geometry>
      <material name="blue"><color rgba="0 0 0.8 1"/></material>
    </visual>
    <collision>
      <geometry><box size="0.6 0.4 0.2"/></geometry>
    </collision>
    <inertial>
      <mass value="${chassis_mass}"/>
      <inertia ixx="0.166" ixy="0" ixz="0" iyy="0.333" iyz="0" izz="0.433"/>
    </inertial>
  </link>

  <xacro:macro name="wheel" params="prefix x_reflect y_reflect">
    <link name="${prefix}_wheel">
      <visual>
        <geometry><cylinder radius="0.15" length="0.08"/></geometry>
        <material name="black"><color rgba="0 0 0 1"/></material>
      </visual>
      <collision>
        <geometry><cylinder radius="0.15" length="0.08"/></geometry>
      </collision>
      <inertial>
        <mass value="${wheel_mass}"/>
        <inertia ixx="0.01" ixy="0" ixz="0" iyy="0.01" iyz="0" izz="0.017"/>
      </inertial>
    </link>

    <joint name="${prefix}_wheel_joint" type="continuous">
      <parent link="base_link"/>
      <child link="${prefix}_wheel"/>
      <origin xyz="${x_reflect * 0.2} ${y_reflect * 0.24} 0" rpy="-1.5708 0 0"/>
      <axis xyz="0 0 1"/>
    </joint>
  </xacro:macro>

  <xacro:wheel prefix="front_left" x_reflect="1" y_reflect="1" />
  <xacro:wheel prefix="front_right" x_reflect="1" y_reflect="-1" />
  <xacro:wheel prefix="rear_left" x_reflect="-1" y_reflect="1" />
  <xacro:wheel prefix="rear_right" x_reflect="-1" y_reflect="-1" />

  <gazebo>
    <plugin name="skid_steer_drive" filename="libgazebo_ros_diff_drive.so">
      <ros>
        <namespace>/</namespace>
        <remapping>cmd_vel:=cmd_vel</remapping>
        <remapping>odom:=odom</remapping>
      </ros>
      <update_rate>50.0</update_rate>
      
      <num_wheel_pairs>2</num_wheel_pairs>
      
      <left_joint>front_left_wheel_joint</left_joint>
      <right_joint>front_right_wheel_joint</right_joint>
      <left_joint>rear_left_wheel_joint</left_joint>
      <right_joint>rear_right_wheel_joint</right_joint>
      
      <wheel_separation>0.48</wheel_separation>
      <wheel_diameter>0.30</wheel_diameter>
      <max_wheel_torque>50</max_wheel_torque>
      <max_wheel_acceleration>1.0</max_wheel_acceleration>
      
      <publish_odom>true</publish_odom>
      <publish_odom_tf>true</publish_odom_tf>
      <publish_wheel_tf>true</publish_wheel_tf>
      <odometry_frame>odom</odometry_frame>
      <robot_base_frame>base_footprint</robot_base_frame>
    </plugin>
  </gazebo>

  <link name="lidar_link"/>
  <joint name="lidar_joint" type="fixed">
    <parent link="base_link"/>
    <child link="lidar_link"/>
    <origin xyz="0 0 0.12" rpy="0 0 0"/>
  </joint>
  <gazebo reference="lidar_link">
    <sensor type="ray" name="lidar">
      <pose>0 0 0 0 0 0</pose>
      <visualize>true</visualize>
      <update_rate>10</update_rate>
      <ray>
        <scan>
          <horizontal>
            <samples>360</samples>
            <resolution>1</resolution>
            <min_angle>-3.14159</min_angle>
            <max_angle>3.14159</max_angle>
          </horizontal>
        </scan>
        <range>
          <min>0.3</min>
          <max>12.0</max>
        </range>
      </ray>
      <plugin name="gazebo_ros_lidar" filename="libgazebo_ros_ray_sensor.so">
        <ros><remapping>~/out:=scan</remapping></ros>
        <output_type>sensor_msgs/LaserScan</output_type>
        <frame_name>lidar_link</frame_name>
      </plugin>
    </sensor>
  </gazebo>

  <link name="imu_link"/>
  <joint name="imu_joint" type="fixed">
    <parent link="base_link"/>
    <child link="imu_link"/>
    <origin xyz="0 0 0" rpy="0 0 0"/>
  </joint>
  <gazebo reference="imu_link">
    <sensor name="imu_sensor" type="imu">
      <plugin name="gazebo_ros_imu_sensor" filename="libgazebo_ros_imu_sensor.so">
        <ros><remapping>~/out:=imu</remapping></ros>
        <initial_orientation_as_reference>false</initial_orientation_as_reference>
      </plugin>
      <always_on>true</always_on>
      <update_rate>100</update_rate>
    </sensor>
  </gazebo>

  <link name="gps_link"/>
  <joint name="gps_joint" type="fixed">
    <parent link="base_link"/>
    <child link="gps_link"/>
    <origin xyz="-0.2 0 0.1" rpy="0 0 0"/>
  </joint>
  <gazebo reference="gps_link">
    <sensor name="gps_sensor" type="gps">
      <plugin name="gazebo_ros_gps_sensor" filename="libgazebo_ros_gps_sensor.so">
        <ros><remapping>~/out:=gps/fix</remapping></ros>
      </plugin>
      <always_on>true</always_on>
      <update_rate>10</update_rate>
    </sensor>
  </gazebo>

  <link name="camera_link"/>
  <joint name="camera_joint" type="fixed">
    <parent link="base_link"/>
    <child link="camera_link"/>
    <origin xyz="0.3 0 0.05" rpy="0 0 0"/>
  </joint>
  <gazebo reference="camera_link">
    <sensor type="camera" name="standard_camera">
      <update_rate>30.0</update_rate>
      <camera name="head">
        <horizontal_fov>1.3962634</horizontal_fov>
        <image><width>800</width><height>800</height><format>R8G8B8</format></image>
        <clip><near>0.02</near><far>300</far></clip>
      </camera>
      <plugin name="gazebo_ros_camera" filename="libgazebo_ros_camera.so">
        <ros><namespace>camera</namespace></ros>
        <camera_name>rgb</camera_name>
      </plugin>
    </sensor>
  </gazebo>

  <link name="zed2_link"/>
  <joint name="zed2_joint" type="fixed">
    <parent link="base_link"/>
    <child link="zed2_link"/>
    <origin xyz="0.25 0 0.15" rpy="0 0 0"/>
  </joint>
  <gazebo reference="zed2_link">
    <sensor type="multicamera" name="stereo_camera">
      <update_rate>30.0</update_rate>
      <camera name="left">
        <pose>0 0.06 0 0 0 0</pose>
        <horizontal_fov>1.9</horizontal_fov>
        <image><width>1280</width><height>720</height><format>R8G8B8</format></image>
        <clip><near>0.1</near><far>100</far></clip>
      </camera>
      <camera name="right">
        <pose>0 -0.06 0 0 0 0</pose>
        <horizontal_fov>1.9</horizontal_fov>
        <image><width>1280</width><height>720</height><format>R8G8B8</format></image>
        <clip><near>0.1</near><far>100</far></clip>
      </camera>
      <plugin name="stereo_camera_controller" filename="libgazebo_ros_camera.so">
        <ros><namespace>zed2</namespace></ros>
        <camera_name>stereo</camera_name>
      </plugin>
    </sensor>
  </gazebo>
<gazebo reference="base_link">
    <material>Gazebo/Blue</material>
  </gazebo>
  
  <gazebo reference="front_left_wheel">
    <material>Gazebo/Black</material>
  </gazebo>
  
  <gazebo reference="front_right_wheel">
    <material>Gazebo/Black</material>
  </gazebo>
  
  <gazebo reference="rear_left_wheel">
    <material>Gazebo/Black</material>
  </gazebo>
  
  <gazebo reference="rear_right_wheel">
    <material>Gazebo/Black</material>
  </gazebo>
</robot>